examples/aapl_l2_book.csv
# Type,OrderId,Side,Price,Quantity
# Format: A=Add, X=Cancel, E=Execute
# Prices in dollars (e.g. 224.95 -> 22495 ticks)
A,1001,B,224.95,500
A,1002,B,224.96,800
A,1003,B,224.97,1200
A,1004,B,224.98,2500
A,1005,B,224.99,3400
A,1006,S,225.00,3100
A,1007,S,225.01,2200
A,1008,S,225.02,1500
A,1009,S,225.03,900
A,1010,S,225.04,600
A,1011,B,224.99,1500
A,1012,S,225.00,1000
X,1001,0,0,0
E,1006,0,225.00,500
A,1013,B,224.98,750
A,1014,S,225.01,850
